Workbook

Sheet HOJA BASICA
B2: CULTIVO | C2: ARANDANO | D2: DPTO. - PROV. | E2: LAREDO
B3: VARIEDAD | C3: Biloxi | D3: SIST. RIEGO | E3: GOTEO
B4: PERIOD. VEGETATIVO | C4: 1 año aprox | D4: EPOCA CULTIVO | E4: Octubre - Marzo
B5: DISTANCIAMIENTO SURCOS (m) | C5: 0.25 | D5: DENSIDAD POBLACIONAL | E5: 5000
B6: DISTANCIAMIENTO ENTRE PL (m) | C6: 0.25 | D6: MONEDA | E6: DOLARES
B7: NIVEL TECNOLOGICO | C7: MEDIO | D7: ÁREA DE SIEMBRA | E7: 1 ha
B8: Producción (Tn/ha) | C8: 15000 | D8: CAMPAÑA AGRÍCOLA | E8: 7 Meses
B11: HOJA DE DATOS BÁSICOS
B13: CONCEPTOS | C13: CLASIFICACIÓN | D13: VALOR UNITARIO | E13: VALOR UNITARIO(DOLARES) | F13: Unidad
B14: Mano de Obra
B15: Mano de Obra | C15: Costo variable | D15: 12.68 | E15: =D15/$G$18 -> 3.7514793 | F15: Jornal
B16: PREPARACIÓN DE TERRENO
B17: Limpieza de campo | C17: Costo variable | D17: 150 | E17: =D17/$G$18 -> 44.378698 | F17: ha
B18: Trasplante | C18: Costo variable | D18: 60 | E18: =D18/$G$18 -> 17.751479 | F18: Tarea | G18: 3.38
B19: Riego | C19: Costo variable | D19: =+$D$15 -> 12.68 | E19: =D19/$G$18 -> 3.7514793 | F19: Jornal
B20: Resiembra | C20: Costo variable | D20: =+$D$15 -> 12.68 | E20: =D20/$G$18 -> 3.7514793 | F20: Jornal
B21: COSECHA
B22: Guardiania | C22: Costo fijo | D22: 60 | E22: =D22/$G$18 -> 17.751479 | F22: Dia
B23: Personal Cosechador | C23: Costo Variable | D23: 50 | E23: =D23/$G$18 -> 14.792899 | F23: Jornal
B24: LABORES CULTURALES
B25: Fumigacion personal | C25: Costo variable | D25: 60 | E25: =D25/$G$18 -> 17.751479 | F25: Ha
B26: Limpieza de canales o acequias | C26: Costo variable | D26: 50 | E26: =D26/$G$18 -> 14.792899 | F26: Jornal
B27: Deshierbo personal | C27: Costo variable | D27: =+$D$16 | E27: =D27/$G$18 -> 0 | F27: =+$F$16
B28: Riego personal | C28: Costo variable | D28: 25.35 | E28: =D28/$G$18 -> 7.5 | F28: =+$F$16
B29: Maquinaria
B30: Mochila Fumigadora | C30: Costo variable | D30: 160 | E30: =D30/$G$18 -> 47.337278 | F30: Hora
B31: Tijeras | C31: Costo variable | D31: 160 | E31: =D31/$G$18 -> 47.337278 | F31: Hora
B32: Equipo:
B33: Bomba de mochila palanca | C33: Costo fijo | D33: 250 | E33: =D33/$G$18 -> 73.964497 | F33: Unidad
B34: Fertilizantes:
B35: MACRONUTRIENTES | C35: Costo variable | D35: 10 | E35: =D35/$G$18 -> 2.9585799 | F35: 1kg
B36: MICRONUTRIENTES | C36: Costo variable | D36: 10 | E36: =D36/$G$18 -> 2.9585799 | F36: 1kg
B37: OTROS( CALCIO-BORO) | C37: Costo variable | D37: 10 | E37: =D37/$G$18 -> 2.9585799 | F37: 1kg
B38: Otros
B39: Agua | C39: Costo fijo | D39: 400 | E39: =D39/$G$18 -> 118.3432 | F39: Campaña
B40: Alquiler del terreno | C40: Costo fijo | D40: 5000 | E40: =D40/$G$18 -> 1479.2899 | F40: Ha
B41: Pasajes | C41: Costo variable | D41: 3 | E41: =D41/$G$18 -> 0.88757396 | F41: Unidad

Sheet Costeo General
A2: Densidad de plantas (Ha) | B2: 5000 | C2: Total de Macetas | D2: 44 | H2: TOTAL | I2: =K23+K50+K78 -> 4451.008
A4: Nuestra area | B4: =(D2*10000)/B2 -> 88 | C4: metros cuadrados
A6: Mes - Setiembre | M6: Tipo de Cambio | P6: MES - SEPTIEMBRE
A7: Semana( Lunes- Viernes) | B7: Rubro | C7: Actividad | D7: Unidad | E7: Cantidad (88 m2) | F7: Cantidad en Ha | G7: Dias | H7: Costo Unitario (soles) | I7: Costo Unitario (Dolares) | J7: Costo Total (Dólares) | K7: Costo Total (Dólares) * Ha | M7: 1 Dolar = 3.38 Soles | P7: Semana | Q7: Rubro | R7: Total (88 M2)
A8: 1 | B8: Mano de obra | C8: Pasajes - Riego | D8: Por personal | E8: 2 | F8: 4 | G8: 6 | H8: 3 | I8: =H8/M10 -> 0.88757396 | J8: =I8*E8*G8 -> 10.650888 | K8: =F8*G8*I8 -> 21.301775 | P8: Semena 1 | Q8: Mano de obra | R8: =J8+J9 -> 55.650888
C9: Labores en campo | D9: Horas | E9: 2 | F9: 4 | G9: 6 | H9: =I9*M10 -> 12.675 | I9: 3.75 | J9: =I9*E9*G9 -> 45 | K9: =F9*G9*I9 -> 90 | M9: 1 | N9: Dólar | P9: Semana 2 | Q9: Mano de obra | R9: =J10+J11 -> 55.650888
A10: 2 | B10: Mano de obra | C10: Pasajes - Riego | D10: Por personal | E10: 2 | F10: 4 | G10: 6 | H10: 3 | I10: =H10/$M$10 -> 0.88757396 | J10: =I10*E10*G10 -> 10.650888 | K10: =F10*G10*I10 -> 21.301775 | M10: 3.38 | N10: Soles | P10: Semana 3 | Q10: Mano de obra | R10: =J12+J13 -> 12.526627
C11: Labores en campo | D11: Horas | E11: 2 | F11: 4 | G11: 6 | H11: 12.675 | I11: =H11/M10 -> 3.75 | J11: =I11*E11*G11 -> 45 | K11: =F11*G11*I11 -> 90 | Q11: Insumos | R11: =J14 -> 13.313609
A12: 3 | B12: Mano de obra | C12: Pasajes - Riego | D12: Por personal | E12: 2 | F12: 6 | G12: 6 | H12: 3 | I12: =H12/M10 -> 0.88757396 | J12: =I12*E12*G12 -> 10.650888 | K12: =F12*G12*I12 -> 31.952663 | M12: 8 horas de jornal (dolares) | N12: 1 hora de jornal (dolares) | Q12: Maquinaria - Servicios | R12: =J15+J16 -> 5.9171598
C13: Labores en campo- Limpieza de Pozo | D13: Horas | E13: 0.5 | F13: 8 | G13: 1 | H13: 12.68 | I13: =H13/M10 -> 3.7514793 | J13: =I13*E13 -> 1.8757396 | K13: =F13*G13*I13 -> 30.011834 | M13: 30 | N13: =M13/8 -> 3.75 | P13: Semana 4 | Q13: Mano de obra | R13: =J17+J18 -> 55.668639
B14: Insumos | C14: Probador de humedad del suelo | D14: Unidad | E14: 1 | F14: 1 | H14: 45 | I14: =H14/$M$10 -> 13.313609 | J14: =I14*E14 -> 13.313609 | K14: =F14*I14 -> 13.313609 | Q14: Insumos | R14: =J19+J20 -> 1.4792899
B15: Maquinaria - servicios | C15: Alquiler Tijeras de poda | D15: Unidad | E15: 1 | F15: 3 | G15: 1 | H15: 10 | I15: =H15/$M$10 -> 2.9585799 | J15: =I15*E15*G15 -> 2.9585799 | K15: =F15*G15*I15 -> 8.8757396 | P15: Semana 5 | Q15: Mano de obra | R15: =J21+J22 -> 18.550296
B16: Maquinaria - servicios | C16: Alquiler - Mochila manual | D16: Unidad | E16: 1 | F16: 3 | G16: 1 | H16: 10 | I16: =H16/$M$10 -> 2.9585799 | J16: =I16*E16*G16 -> 2.9585799 | K16: =F16*G16*I16 -> 8.8757396 | P16: TOTAL | R16: =SUM(R8:R15) -> 218.7574
A17: 4 | B17: Mano de obra | C17: Pasajes - Riego | D17: Por personal | E17: 2 | F17: 4 | G17: 6 | H17: 3 | I17: =H17/$M$10 -> 0.88757396 | J17: =I17*E17*G17 -> 10.650888 | K17: =F17*G17*I17 -> 21.301775 | M17: Marco de plantacion
C18: Labores en campo | D18: Horas | E18: 2 | F18: 4 | G18: 6 | H18: 12.68 | I18: =H18/M10 -> 3.7514793 | J18: =I18*E18*G18 -> 45.017751 | K18: =F18*G18*I18 -> 90.035503 | M18: macetas | N18: 0.4
B19: Insumos | C19: Palos para Cartel | D19: Unidad | E19: 2 | F19: 2 | H19: 2 | I19: =H19/$M$10 -> 0.59171598 | J19: =I19*E19 -> 1.183432 | K19: =F19*I19 -> 1.183432 | M19: surco | N19: 2
C20: Imagen y otros | D20: 1 | E20: 1 | F20: 1 | H20: 1 | I20: =H20/$M$10 -> 0.29585799 | J20: =I20*E20 -> 0.29585799 | K20: =F20*I20 -> 0.29585799
A21: 5 | B21: Mano de obra | C21: Pasajes - Riego | D21: Por personal | E21: 2 | F21: 4 | G21: 2 | H21: 3 | I21: =H21/$M$10 -> 0.88757396 | J21: =I21*E21*G21 -> 3.5502959 | K21: =F21*G21*I21 -> 7.1005917
C22: Labores en campo | D22: Horas | E22: 2 | F22: 4 | G22: 2 | H22: 12.68 | I22: 3.75 | J22: =I22*E22*G22 -> 15 | K22: =F22*G22*I22 -> 30
A23: TOTAL | B23: - | C23: - | D23: - | E23: - | G23: - | H23: =SUM(H8:H22) -> 146.39 | I23: =SUM(I8:I22) -> 43.309172 | J23: =SUM(J8:J22) -> 218.7574 | K23: =SUM(K8:K22) -> 465.5503
A26: Mes - Octubre | P26: MES - SEPTIEMBRE
A27: Semana( Lunes- Viernes) | B27: Rubro | C27: Actividad | D27: Unidad | E27: Cantidad | F27: Cantidad en Ha | G27: Dias | H27: Costo Unitario (soles) | I27: Costo Unitario (Dolares) | J27: Costo Total (Dólares) | K27: Costo Total (Dólares) * Ha | P27: Semana | Q27: Rubro | R27: Total (88 M2)
A28: 1 | B28: Mano de obra | C28: Pasajes - Riego | D28: Por personal | E28: 2 | F28: 4 | G28: 4 | H28: 3 | I28: =H28/$M$10 -> 0.88757396 | J28: =I28*E28*G28 -> 7.1005917 | K28: =F28*G28*I28 -> 14.201183 | P28: SEMANA 1 | Q28: Mano de obra | R28: =J28+J29 -> 37.112426
C29: Labores en campo | D29: Horas | E29: 2 | F29: 4 | G29: 4 | H29: 12.68 | I29: =H29/M10 -> 3.7514793 | J29: =I29*E29*G29 -> 30.011834 | K29: =F29*G29*I29 -> 60.023669 | P29: SEMANA 2 | Q29: Mano de obra | R29: =J30+J33 -> 55.668639
A30: 2 | B30: Mano de obra | C30: Pasajes - Riego | D30: Por personal | E30: 2 | F30: 4 | G30: 6 | H30: 3 | I30: =H30/$M$10 -> 0.88757396 | J30: =I30*E30*G30 -> 10.650888 | K30: =F30*G30*I30 -> 21.301775 | Q30: Insumos | R30: =J31+J32 -> 3.5502959
B31: Insumos | C31: Materiales para arreglo del tanque | D31: Boldimix | E31: 1 | G31: 1 | H31: 10 | I31: =H31/$M$10 -> 2.9585799 | J31: =I31*E31 -> 2.9585799 | P31: SEMANA 3 | Q31: Mano de obra | R31: =J34+J35 -> 55.650888
D32: Teflones | E32: 2 | G32: 1 | H32: 1 | I32: =H32/$M$10 -> 0.29585799 | J32: =I32*E32 -> 0.59171598 | Q32: Insumos | R32: =J36 -> 13.313609
B33: Mano de obra | C33: Labores en campo | D33: Horas | E33: 2 | F33: 4 | G33: 6 | H33: 12.68 | I33: =H33/M10 -> 3.7514793 | J33: =I33*E33*G33 -> 45.017751 | K33: =F33*G33*I33 -> 90.035503 | Q33: Maquinaria - Servicios | R33: =J37+J38 -> 2.9585799
A34: 3 | B34: Mano de obra | C34: Pasajes - Riego | D34: Por personal | E34: 2 | F34: 4 | G34: 6 | H34: 3 | I34: =H34/$M$10 -> 0.88757396 | J34: =I34*E34*G34 -> 10.650888 | K34: =F34*G34*I34 -> 21.301775 | P34: SEMANA 4 | Q34: Mano de obra | R34: =J39+J40 -> 55.668639
C35: Labores en campo | D35: Horas | E35: 2 | F35: 4 | G35: 6 | H35: 12.68 | I35: 3.75 | J35: =I35*E35*G35 -> 45 | K35: =F35*G35*I35 -> 90 | Q35: Insumos | R35: =SUM(J41:J46) -> 22.189349
B36: Insumos | C36: Ph-metro | D36: Unidad | E36: 1 | F36: 1 | G36: 0 | H36: 45 | I36: =H36/$M$10 -> 13.313609 | J36: =I36*E36 -> 13.313609 | K36: =F36*I36 -> 13.313609 | P36: SEMANA 5 | Q36: Mano de obra | R36: =J47+J48 -> 46.37574
B37: Maquinaria - servicios | C37: Tijeras de poda | D37: Hora | E37: 0.5 | F37: 3 | G37: 1 | H37: 10 | I37: =H37/$M$10 -> 2.9585799 | J37: =I37*E37*G37 -> 1.4792899 | K37: =F37*G37*I37 -> 8.8757396 | Q37: Insumos | R37: =J49 -> 72.485207
B38: Maquinaria - servicios | C38: Mochila manual | D38: Unidad | E38: 0.5 | F38: 3 | G38: 1 | H38: 10 | I38: =H38/$M$10 -> 2.9585799 | J38: =I38*E38*G38 -> 1.4792899 | K38: =F38*G38*I38 -> 8.8757396 | P38: TOTAL | R38: =SUM(R28:R37) -> 364.97337
A39: 4 | B39: Mano de obra | C39: Pasajes - Riego | D39: Por personal | E39: 2 | F39: 4 | G39: 6 | H39: 3 | I39: =H39/$M$10 -> 0.88757396 | J39: =I39*E39*G39 -> 10.650888 | K39: =F39*G39*I39 -> 21.301775
C40: Labores en campo | D40: Horas | E40: 2 | F40: 4 | G40: 6 | H40: 12.68 | I40: =H40/M10 -> 3.7514793 | J40: =I40*E40*G40 -> 45.017751 | K40: =F40*G40*I40 -> 90.035503
B41: Insumos | C41: FERTILIZANTE GRUPO 1 - Total | D41: kilo | E41: 1 | F41: 3.55 | G41: 7 | H41: 10 | I41: =H41/$M$10 -> 2.9585799 | J41: =I41*E41 -> 2.9585799 | K41: =F41*G41*I41 -> 73.52071
C42: FERTILIZANTE GRUPO 2 - Total | D42: kilo | E42: 1 | F42: 1.64 | G42: 7 | H42: 10 | I42: =H42/$M$10 -> 2.9585799 | J42: =I42*E42 -> 2.9585799 | K42: =F42*G42*I42 -> 33.964497
C43: FERTILIZANTE GRUPO 3 -Total | D43: kilo | E43: 1 | F43: 3.18 | G43: 7 | H43: 10 | I43: =H43/$M$10 -> 2.9585799 | J43: =I43*E43 -> 2.9585799 | K43: =F43*G43*I43 -> 65.857988
C44: Balanza | D44: Unidad | E44: 1 | F44: 1 | H44: 30 | I44: =H44/$M$10 -> 8.8757396 | J44: =I44*E44 -> 8.8757396 | K44: =F44*I44 -> 8.8757396
C45: Balde | D45: Unidad | E45: 1 | F45: - | G45: - | H45: 10 | I45: =H45/$M$10 -> 2.9585799 | J45: =I45*E45 -> 2.9585799 | K45: 2.96
...

Sheet Rubro Mano de Obra
D2: TOTAL | E2: =L17+L32+L49 -> 1416.4083 | H2: =(E2/'Costeo General'!I2)*100 -> 31.822191 | I2: %
R3: Semana (Lunes- Viernes) | S3: Costo Total en 88 m2 | T3: Costo Total en 1 Ha
N4: Area | O4: Ha | R4: 1 | S4: =SUM(K7:K8) -> 55.668639 | T4: =SUM(L7:L8) -> 111.33728
C5: Mes - Setiembre | N5: 88 | O5: 10000 | R5: 2 | S5: =K9+K10 -> 55.668639 | T5: =L9+L10 -> 111.33728
C6: Semana( Lunes- Viernes) | D6: Actividad | E6: Unidad | F6: Cantidad (88m2) | G6: Cantidad en Ha | H6: Dias | I6: Costo Unitario (soles) | J6: Costo Unitario (Dolares) | K6: Costo Total (Dólares) | L6: Costo Total (Dólares) * Ha | R6: 3 | S6: =K11+K12 -> 12.526627 | T6: =L11+L12 -> 61.964497
C7: 1 | D7: Pasajes(Ida y Vuelta) | E7: Por personal | F7: 2 | G7: 4 | H7: 6 | I7: 3 | J7: =I7/$N$9 -> 0.88757396 | K7: =J7*F7*H7 -> 10.650888 | L7: =G7*H7*J7 -> 21.301775 | R7: 4 | S7: =K13+K14 -> 55.668639 | T7: =L13+L14 -> 111.33728
D8: Labores en campo | E8: Horas | F8: 2 | G8: 4 | H8: 6 | I8: 12.68 | J8: =I8/$N$9 -> 3.7514793 | K8: =J8*F8*H8 -> 45.017751 | L8: =G8*H8*J8 -> 90.035503 | N8: 1 | O8: Dólar | R8: 5 | S8: =K15+K16 -> 18.556213 | T8: =L15+L16 -> 37.112426
C9: 2 | D9: Pasajes(Ida y Vuelta) | E9: Por personal | F9: 2 | G9: 4 | H9: 6 | I9: 3 | J9: =I9/$N$9 -> 0.88757396 | K9: =J9*F9*H9 -> 10.650888 | L9: =G9*H9*J9 -> 21.301775 | N9: 3.38 | O9: Soles | R9: TOTAL | S9: =SUM(S4:S8) -> 198.08876 | T9: =SUM(T4:T8) -> 433.08876
D10: Labores en campo | E10: Horas | F10: 2 | G10: 4 | H10: 6 | I10: 12.68 | J10: =I10/$N$9 -> 3.7514793 | K10: =J10*F10*H10 -> 45.017751 | L10: =G10*H10*J10 -> 90.035503
C11: 3 | D11: Pasajes(Ida y Vuelta) | E11: Por personal | F11: 2 | G11: 6 | H11: 6 | I11: 3 | J11: =I11/$N$9 -> 0.88757396 | K11: =J11*F11*H11 -> 10.650888 | L11: =G11*H11*J11 -> 31.952663 | N11: Horas | O11: COSTO(Soles)
D12: Labores en campo- Limpieza de Pozo | E12: Horas | F12: 0.5 | G12: 8 | H12: 1 | I12: 12.68 | J12: =I12/$N$9 -> 3.7514793 | K12: =J12*F12*H12 -> 1.8757396 | L12: =G12*H12*J12 -> 30.011834 | N12: 1 | O12: 25.35
C13: 4 | D13: Pasajes(Ida y Vuelta) | E13: Por personal | F13: 2 | G13: 4 | H13: 6 | I13: 3 | J13: =I13/$N$9 -> 0.88757396 | K13: =J13*F13*H13 -> 10.650888 | L13: =G13*H13*J13 -> 21.301775
D14: Labores en campo | E14: Horas | F14: 2 | G14: 4 | H14: 6 | I14: 12.68 | J14: =I14/$N$9 -> 3.7514793 | K14: =J14*F14*H14 -> 45.017751 | L14: =G14*H14*J14 -> 90.035503
C15: 5 | D15: Pasajes(Ida y Vuelta) | E15: Por personal | F15: 2 | G15: 4 | H15: 2 | I15: 3 | J15: =I15/$N$9 -> 0.88757396 | K15: =J15*F15*H15 -> 3.5502959 | L15: =G15*H15*J15 -> 7.1005917
D16: Labores en campo | E16: Horas | F16: 2 | G16: 4 | H16: 2 | I16: 12.68 | J16: =I16/$N$9 -> 3.7514793 | K16: =J16*F16*H16 -> 15.005917 | L16: =G16*H16*J16 -> 30.011834
C17: TOTAL | D17: - | E17: - | F17: - | H17: - | I17: =SUM(I7:I16) -> 78.4 | J17: =SUM(J7:J16) -> 23.195266 | K17: =SUM(K7:K16) -> 198.08876 | L17: =SUM(L7:L16) -> 433.08876
O19: Meses | P19: Gastos - Ha
C20: Mes - Octubre | O20: Septiembre | P20: =L17 -> 433.08876
C21: Semana( Lunes- Viernes) | D21: Actividad | E21: Unidad | F21: Cantidad (88m2) | G21: Cantidad en Ha | H21: Dias | I21: Costo Unitario (soles) | J21: Costo Unitario (Dolares) | K21: Costo Total (Dólares) | L21: Costo Total (Dólares) * Ha | O21: Octubre | P21: =L32 -> 500.85799 | R21: Semana (Lunes- Viernes) | S21: Costo Total en 88 m2 | T21: Costo Total en 1 Ha
C22: 1 | D22: Pasajes(Ida y Vuelta) | E22: Por personal | F22: 2 | G22: 4 | H22: 4 | I22: 3 | J22: =I22/$N$9 -> 0.88757396 | K22: =J22*F22*H22 -> 7.1005917 | L22: =J22*H22*G22 -> 14.201183 | O22: Noviembre | P22: =L49 -> 482.46154 | R22: 1 | S22: =K22+K23 -> 37.100592 | T22: =L22+L23 -> 74.201183
D23: Labores en campo | E23: Horas | F23: 2 | G23: 4 | H23: 4 | I23: =O12 -> 25.35 | J23: 3.75 | K23: =J23*F23*H23 -> 30 | L23: =J23*H23*G23 -> 60 | O23: Diciembre | R23: 2 | S23: =K24+K25 -> 55.650888 | T23: =L24+L25 -> 111.30178
C24: 2 | D24: Pasajes(Ida y Vuelta) | E24: Por personal | F24: 2 | G24: 4 | H24: 6 | I24: 3 | J24: =I24/$N$9 -> 0.88757396 | K24: =J24*F24*H24 -> 10.650888 | L24: =J24*H24*G24 -> 21.301775 | O24: Total | P24: =SUM(P20:P23) -> 1416.4083 | R24: 3 | S24: =K26+K27 -> 78.150888 | T24: =L26+L27 -> 111.30178
D25: Labores en campo | E25: Horas | F25: 2 | G25: 4 | H25: 6 | I25: =O12 -> 25.35 | J25: 3.75 | K25: =J25*F25*H25 -> 45 | L25: =J25*H25*G25 -> 90 | R25: 4 | S25: =K28+K29 -> 55.650888 | T25: =L28+L29 -> 111.30178
C26: 3 | D26: Pasajes(Ida y Vuelta) | E26: Por personal | F26: 2 | G26: 4 | H26: 6 | I26: 3 | J26: =I26/$N$9 -> 0.88757396 | K26: =J26*F26*H26 -> 10.650888 | L26: =J26*H26*G26 -> 21.301775 | R26: 5 | S26: =K30+K31 -> 46.37574 | T26: =L30+L31 -> 92.751479
D27: Labores en campo | E27: Horas | F27: 3 | G27: 4 | H27: 6 | I27: =O12 -> 25.35 | J27: 3.75 | K27: =J27*F27*H27 -> 67.5 | L27: =J27*H27*G27 -> 90 | R27: TOTAL | S27: =SUM(S22:S26) -> 272.92899 | T27: =SUM(T22:T26) -> 500.85799
C28: 4 | D28: Pasajes(Ida y Vuelta) | E28: Por personal | F28: 2 | G28: 4 | H28: 6 | I28: 3 | J28: =I28/$N$9 -> 0.88757396 | K28: =J28*F28*H28 -> 10.650888 | L28: =J28*H28*G28 -> 21.301775
D29: Labores en campo | E29: Horas | F29: 2 | G29: 4 | H29: 6 | I29: =O12 -> 25.35 | J29: 3.75 | K29: =J29*F29*H29 -> 45 | L29: =J29*H29*G29 -> 90
C30: 5 | D30: Pasajes(Ida y Vuelta) | E30: Por personal | F30: 2 | G30: 4 | H30: 5 | I30: 3 | J30: =I30/$N$9 -> 0.88757396 | K30: =J30*F30*H30 -> 8.8757396 | L30: =J30*H30*G30 -> 17.751479
D31: Labores en campo | E31: Horas | F31: 2 | G31: 4 | H31: 5 | I31: =O12 -> 25.35 | J31: 3.75 | K31: =J31*F31*H31 -> 37.5 | L31: =J31*H31*G31 -> 75
C32: Total | D32: - | E32: - | F32: - | H32: - | J32: =SUM(J21:J31) -> 23.18787 | K32: =SUM(K21:K31) -> 272.92899 | L32: =SUM(L22:L31) -> 500.85799
C35: Mes - Noviembre
C36: Semana( Lunes- Viernes) | D36: Actividad | E36: Unidad | F36: Cantidad | G36: Cantidad en Ha | H36: Dias | I36: Costo Unitario (soles) | J36: Costo Unitario (Dolares) | K36: Costo Total (Dólares) | L36: Costo Total (Dólares) * Ha | R36: Semana (Lunes- Viernes) | S36: Costo Total en 88 m2 | T36: Costo Total en 1 Ha
C37: 1 | D37: Pasajes(Ida y Vuelta) | E37: Por personal | F37: 2 | G37: 4 | H37: 1 | I37: 3 | J37: =I37/N9 -> 0.88757396 | K37: =J37*F37*H37 -> 1.7751479 | L37: =G37*H37*J37 -> 3.5502959 | R37: 1 | S37: =K37+K38 -> 9.2781065 | T37: =L37+L38 -> 18.556213
D38: Riego diario| | E38: Horas | F38: 2 | G38: 4 | H38: 1 | I38: 12.68 | J38: =I38/$N$9 -> 3.7514793 | K38: =J38*F38*H38 -> 7.5029586 | L38: =G38*H38*J38 -> 15.005917 | R38: 2 | S38: =K39+K40 -> 33.159763 | T38: =L39+L40 -> 111.33728
C39: 2 | D39: Pasajes(Ida y Vuelta) | E39: Por personal | F39: 2 | G39: 4 | H39: 6 | I39: 3 | J39: =I39/$N$9 -> 0.88757396 | K39: =J39*F39*H39 -> 10.650888 | L39: =G39*H39*J39 -> 21.301775 | R39: 3 | S39: =K41+K42 -> 78.177515 | T39: =L41+L42 -> 111.33728
D40: Riego diario | E40: Horas | F40: 1 | G40: 4 | H40: 6 | I40: 12.68 | J40: =I40/$N$9 -> 3.7514793 | K40: =J40*F40*H40 -> 22.508876 | L40: =G40*H40*J40 -> 90.035503 | R40: 4 | S40: =K43+K44 -> 78.177515 | T40: =L43+L44 -> 111.33728
C41: 3 | D41: Pasajes(Ida y Vuelta) | E41: Por personal | F41: 2 | G41: 4 | H41: 6 | I41: 3 | J41: =I41/$N$9 -> 0.88757396 | K41: =J41*F41*H41 -> 10.650888 | L41: =G41*H41*J41 -> 21.301775 | R41: 5 | S41: =K45+K46+K47+K48 -> 64.946746 | T41: =L45+L46+L47+L48 -> 129.89349
D42: Fertiriego | E42: Horas | F42: 3 | G42: 4 | H42: 6 | I42: 12.68 | J42: =I42/$N$9 -> 3.7514793 | K42: =J42*F42*H42 -> 67.526627 | L42: =G42*H42*J42 -> 90.035503 | R42: TOTAL | S42: =SUM(S37:S41) -> 263.73964 | T42: =SUM(T37:T41) -> 482.46154
C43: 4 | D43: Pasajes(Ida y Vuelta) | E43: Por personal | F43: 2 | G43: 4 | H43: 6 | I43: 3 | J43: =I43/$N$9 -> 0.88757396 | K43: =J43*F43*H43 -> 10.650888 | L43: =G43*H43*J43 -> 21.301775
D44: Riego diario| | E44: Horas | F44: 3 | G44: 4 | H44: 6 | I44: 12.68 | J44: =I44/$N$9 -> 3.7514793 | K44: =J44*F44*H44 -> 67.526627 | L44: =G44*H44*J44 -> 90.035503
...

Sheet Copy of Rubro Insumos
A2: Densidad de plantas (Ha) | B2: 5000 | C2: Total de Macetas | D2: 44 | H2: TOTAL | I2: =K21+K34+K45 -> 2911.0715
A4: Nuestra area | B4: =(D2*10000)/B2 -> 88 | C4: metros cuadrados | I4: =(I2/'Costeo General'!I2)*100 -> 65.402521
A6: Mes - Setiembre | M6: Tipo de Cambio
A7: Semana( Lunes- Viernes) | B7: Rubro | C7: Actividad | D7: Unidad | E7: Cantidad (88 m2) | F7: Cantidad (ha) | G7: Dias | H7: Costo Unitario (soles) | I7: Costo Unitario (Dolares) | J7: Costo Total (Dólares) | K7: Costo Total (Dólares) * Ha | M7: 1 Dolar = 3.38 Soles | Q7: Semana (Lunes- Viernes) | R7: Costo Total en 88 m2 | S7: Costo Total en 1 Ha
A8: 1 | B8: Mano de obra | C8: Pasajes - Riego | D8: Por personal | E8: 2 | G8: 6 | H8: 3 | I8: =H8/M10 -> 0.88757396 | J8: =I8*E8*G8 -> 10.650888 | K8: =(J8*10000)/$B$4 -> 1210.3281
C9: Labores en campo | D9: Horas | E9: 2 | G9: 6 | H9: =I9*$M$10 -> 25.35 | I9: 7.5 | J9: =I9*E9*G9 -> 90 | K9: =(J9*10000)/$B$4 -> 10227.273 | M9: 1 | N9: Dólar
A10: 2 | B10: Mano de obra | C10: Pasajes - Riego | D10: Por personal | E10: 2 | G10: 6 | H10: 3 | I10: =H10/$M$10 -> 0.88757396 | J10: =I10*E10*G10 -> 10.650888 | K10: =(J10*10000)/$B$4 -> 1210.3281 | M10: 3.38 | N10: Soles
C11: Labores en campo | D11: Horas | E11: 2 | G11: 6 | H11: =I11*$M$10 -> 25.35 | I11: 7.5 | J11: =I11*E11*G11 -> 90 | K11: =(J11*10000)/$B$4 -> 10227.273
A12: 3 | B12: Mano de obra | C12: Pasajes - Riego | D12: Por personal | E12: 2 | G12: 6 | H12: =I12*$M$10 -> 25.35 | I12: 7.5 | J12: =I12*E12*G12 -> 90 | K12: =(J12*10000)/$B$4 -> 10227.273 | M12: Dolares | N12: 1 Jornal
C13: Labores en campo- Limpieza de Pozo | D13: Horas | E13: 1 | H13: =I13*$M$10 -> 12.675 | I13: =(E13*$M$13)/N13 -> 3.75 | J13: =I13*E13 -> 3.75 | K13: =J13 -> 3.75 | M13: 30 | N13: 8
B14: Materiales e Insumos | C14: Probador de humedad del suelo | D14: Unidad | E14: 1 | F14: 1 | G14: 1 | H14: 45 | I14: =H14/$M$10 -> 13.313609 | J14: =I14*E14 -> 13.313609 | K14: =F14*G14*I14 -> 13.313609 | Q14: 3 | R14: =J14 -> 13.313609 | S14: =K14 -> 13.313609
A15: 4 | B15: Mano de obra | C15: Pasajes - Riego | D15: Por personal | E15: 2 | G15: 6 | H15: 3 | I15: =H15/$M$10 -> 0.88757396 | J15: =I15*E15*G15 -> 10.650888 | K15: =F15*G15*I15 -> 0 | M15: Marco de plantacion
C16: Labores en campo | D16: Horas | E16: 2 | G16: 6 | H16: =I16*$M$10 -> 25.35 | I16: 7.5 | J16: =I16*E16*G16 -> 90 | K16: =F16*G16*I16 -> 0 | M16: macetas | N16: 0.4
B17: Materiales e Insumos | C17: Palos - Cartel | D17: Unidad | E17: 2 | F17: 2 | G17: 1 | H17: 2 | I17: =H17/$M$10 -> 0.59171598 | J17: =I17*E17 -> 1.183432 | K17: =F17*G17*I17 -> 1.183432 | M17: surco | N17: 2 | Q17: 4 | R17: =J17+J18 -> 1.4792899 | S17: =K17+K18 -> 1.4792899
C18: Imagen y otros | D18: 1 | E18: 1 | F18: 1 | G18: 1 | H18: 1 | I18: =H18/$M$10 -> 0.29585799 | J18: =I18*E18 -> 0.29585799 | K18: =F18*G18*I18 -> 0.29585799 | Q18: TOTAL | R18: =SUM(R14:R17) -> 14.792899 | S18: =SUM(S14:S17) -> 14.792899
A19: 5 | B19: Mano de obra | C19: Pasajes - Riego | D19: Por personal | E19: 2 | G19: 6 | H19: 3 | I19: =H19/$M$10 -> 0.88757396 | J19: =I19*E19*G19 -> 10.650888 | K19: =(J19*10000)/$B$4 -> 1210.3281
C20: Labores en campo | D20: Horas | E20: 2 | G20: 6 | H20: =I20*$M$10 -> 25.35 | I20: 7.5 | J20: =I20*E20*G20 -> 90 | K20: =(J20*10000)/$B$4 -> 10227.273
A21: TOTAL | B21: - | C21: - | D21: - | E21: - | G21: - | H21: =H14+H17+H18 -> 48 | I21: =I14+I17+I18 -> 14.201183 | J21: =J14+J17+J18 -> 14.792899 | K21: =K14+K17+K18 -> 14.792899
A24: Mes - Octubre
A25: Semana( Lunes- Viernes) | B25: Rubro | C25: Actividad | D25: Unidad | E25: Cantidad (88 m2) | F25: Cantidad (ha) | G25: Dias | H25: Costo Unitario (soles) | I25: Costo Unitario (Dolares) | J25: Costo Total (Dólares) | K25: Costo Total (Dólares) * Ha | Q25: Semana (Lunes- Viernes) | R25: Costo Total en 88 m2 | S25: Costo Total en 1 Ha
B26: Insumos | C26: Ph-metro | D26: Unidad | E26: 1 | F26: 1 | H26: 45 | I26: =H26/$M$10 -> 13.313609 | J26: =I26*E26 -> 13.313609 | K26: =J26 -> 13.313609 | Q26: 3 | R26: =J26 -> 13.313609
B27: Insumos | C27: FERTILIZANTE GRUPO 1 | D27: kilo | E27: 1 | F27: 3.6 | G27: 7 | H27: 10 | I27: =H27/$M$10 -> 2.9585799 | J27: =I27*E27 -> 2.9585799 | K27: =F27*G27*I27 -> 74.556213 | Q27: 4 | R27: =SUM(J27:J32) -> 22.19574
C28: FERTILIZANTE GRUPO 2 | D28: kilo | E28: 1 | F28: 1.64 | G28: 7 | H28: 10 | I28: =H28/$M$10 -> 2.9585799 | J28: =I28*E28 -> 2.9585799 | K28: =F28*G28*I28 -> 33.964497 | Q28: 5 | R28: =J33 -> 72.485207
C29: FERTILIZANTE FRUPO 3 | D29: kilo | E29: 1 | F29: 3.18 | G29: 7 | H29: 10 | I29: =H29/$M$10 -> 2.9585799 | J29: =I29*E29 -> 2.9585799 | K29: =F29*G29*I29 -> 65.857988 | Q29: TOTAL | R29: =SUM(R27:R28) -> 94.680947 | S29: =SUM(S27:S28) -> 0
C30: Balanza | D30: Unidad | E30: 1 | F30: 1 | H30: 30 | I30: 8.88 | J30: =E30*I30*F30 -> 8.88 | K30: =I30*F30 -> 8.88
C31: Balde | D31: Unidad | E31: 1 | F31: - | G31: - | H31: 10 | I31: 2.96 | J31: =E31*I31 -> 2.96 | K31: =J31 -> 2.96
C32: Jarra | D32: Unidad | E32: 1 | F32: - | G32: - | H32: 5 | I32: 1.48 | J32: =E32*I32 -> 1.48 | K32: =J32 -> 1.48
B33: Insumos | C33: Plastico | D33: mettro | E33: 7 | H33: 35 | I33: =H33/$M$10 -> 10.35503 | J33: =I33*E33 -> 72.485207
A34: TOTAL | H34: =H26+H27+H28+H29+H30+H31+H32+H33 -> 155 | I34: =I26+I27+I28+I29+I30+I31+I32+I33 -> 45.864379 | J34: =J26+J27+J28+J29+J30+J31+J32+J33 -> 107.99456 | K34: =K26+K27+K28+K29+K30+K31+K32+K33 -> 201.01231
A37: Mes - Noviembre
A38: Semana (Lunes- Viernes) | B38: Rubro | C38: Actividad | D38: Unidad | E38: Cantidad (88 m2) | F38: Cantidad (ha) | G38: Dias | H38: Costo Unitario (soles) | I38: Costo Unitario (Dolares) | J38: Costo Total (Dólares) | K38: Costo Total (Dólares) * Ha
B39: Insumo | C39: jeringa | D39: unidad | E39: 1 | F39: 1 | G39: 1 | H39: 1 | I39: =H39/$M$10 -> 0.29585799 | J39: =I39*E39*G39 -> 0.29585799 | K39: =F39*I39*G39 -> 0.29585799 | M39: =K21+K34+K45 -> 2911.0715
A40: 5 | B40: Insumo | C40: Botellas | D40: Unidad | E40: 50 | F40: 10000 | G40: 1 | H40: 0.42 | I40: =H40/$M$10 -> 0.12426036 | J40: =I40*E40*G40 -> 6.2130178 | K40: =F40*G40*I40 -> 1242.6036
C41: Alambre | D41: Kilo | E41: 2 | F41: 227 | G41: 1 | H41: 3 | I41: =H41/$M$10 -> 0.88757396 | J41: =I41*E41*G41 -> 1.7751479 | K41: =F41*G41*I41 -> 201.47929
C42: Microaspersores | D42: Unidad | E42: 88 | F42: 10000 | G42: 1 | H42: 0.2 | I42: =H42/$M$10 -> 0.059171598 | J42: =I42*E42*G42 -> 5.2071006 | K42: =F42*G42*I42 -> 591.71598
C43: Hilo | D43: Unidad | E43: 1 | F43: 113 | G43: 1 | H43: 2 | I43: =H43/$M$10 -> 0.59171598 | J43: =I43*E43*G43 -> 0.59171598 | K43: =F43*G43*I43 -> 66.863905
C44: Palos | D44: Unidad | E44: 8 | F44: 1001 | G44: 1 | H44: 2 | I44: =H44/$M$10 -> 0.59171598 | J44: =I44*E44*G44 -> 4.7337278 | K44: =F44*G44*I44 -> 592.30769 | M44: 1 | N44: 25.35
A45: TOTAL | H45: =H39+H44 -> 3 | I45: =I39+I40+I41+I42+I43+I44 -> 2.5502959 | J45: =J39+J40+J41+J42+J43+J44 -> 18.816568 | K45: =K39+K40+K41+K42+K43+K44 -> 2695.2663
C48: TOTAL INSUMOS - HA | D48: =K21+K34+K45 -> 2911.0715
C51: TOTAL INSUMOS - 88M2 | D51: =J45+J34+J21 -> 141.60402

Sheet Rubro Maquinaria - Servicio
A2: Densidad de plantas (Ha) | B2: 5000 | C2: Total de Macetas | D2: 44 | H2: TOTAL | I2: =K13+K21+K32 -> 76.312308
A4: Nuestra area | B4: =(D2*10000)/B2 -> 88 | C4: metros cuadrados | I4: =(I2/'Costeo General'!I2)*100 -> 1.7144949 | J4: %
A6: Mes - Setiembre | M6: Tipo de Cambio
A7: Semana( Lunes- Viernes) | B7: Rubro | C7: Actividad | D7: Unidad | E7: Cantidad (88 m2) | F7: Cantidad (ha) | G7: Dias | H7: Costo Unitario (soles) | I7: Costo Unitario (Dolares) | J7: Costo Total (Dólares) | K7: Costo Total (Dólares) * Ha | M7: 1 Dolar = 3.38 Soles
A8: 3 | B8: Maquinaria - Serivicio | C8: Probador de humedad de Suelo | D8: Unidad | E8: 1 | F8: 1 | G8: 1 | H8: 45 | I8: =H8/$M$11 -> 13.313609 | J8: 13.31 | K8: =F8*G8*I8 -> 13.313609
B9: Maquinaria - Serivicio | C9: Alquiler de tijeras de poda | D9: Unidad | E9: 1 | F9: 3 | G9: 1 | H9: 10 | I9: =H9/$M$11 -> 2.9585799 | J9: =I9*E9*G9 -> 2.9585799 | K9: =F9*G9*I9 -> 8.8757396 | M9: 1 | N9: Dólar
B10: Maquinaria - Serivicio | C10: Alquiler - Mochila manual | D10: Unidad | E10: 1 | F10: 3 | G10: 1 | H10: 10 | I10: 2.96 | J10: 2.96 | K10: =F10*G10*I10 -> 8.88
A11: 4 | B11: Maquinaria - Serivicio | C11: Palos para cartel | D11: Unidad | E11: 2 | F11: 2 | G11: 1 | H11: 2 | I11: 0.59 | J11: 1.18 | K11: =F11*G11*I11 -> 1.18 | M11: 3.38 | N11: soles
B12: Maquinaria - Serivicio | C12: Imagen del cartel | D12: Unidad | E12: 1 | F12: 1 | G12: 1 | H12: 1 | I12: 0.3 | J12: 0.3 | K12: =F12*G12*I12 -> 0.3
A13: TOTAL | B13: - | C13: - | D13: - | E13: - | G13: - | H13: =SUM(H8:H12) -> 68 | I13: =SUM(I8:I12) -> 20.122189 | J13: =SUM(J8:J12) -> 20.70858 | K13: =SUM(K8:K12) -> 32.549349
A17: Mes - Octubre
A18: Semana( Lunes- Viernes) | B18: Rubro | C18: Actividad | D18: Unidad | E18: Cantidad (88 m2) | F18: Cantidad (ha) | G18: Dias | H18: Costo Unitario (soles) | I18: Costo Unitario (Dolares) | J18: Costo Total (Dólares) | K18: Costo Total (Dólares) * Ha
A19: 3 | B19: Maquinaria - Serivicio | C19: Alquiler de tijeras de poda | D19: Unidad | E19: 0.5 | F19: 3 | G19: 1 | H19: 10 | I19: =H19/$M$11 -> 2.9585799 | J19: =I19*E19*G19 -> 1.4792899 | K19: =F19*G19*I19 -> 8.8757396
B20: Maquinaria - Serivicio | C20: Alquiler - Mochila manual | D20: Unidad | E20: 0.5 | F20: 3 | G20: 1 | H20: 10 | I20: =H20/$M$11 -> 2.9585799 | J20: =I20*E20*G20 -> 1.4792899 | K20: =F20*G20*I20 -> 8.8757396
A21: TOTAL | B21: - | C21: - | D21: - | E21: - | G21: - | H21: =SUM(H19:H20) -> 20 | I21: =SUM(I19:I20) -> 5.9171598 | J21: =SUM(J19:J20) -> 2.9585799 | K21: =SUM(K19:K20) -> 17.751479
A25: Mes - Noviembre
A26: Semana( Lunes- Viernes) | B26: Rubro | C26: Actividad | D26: Unidad | E26: Cantidad (88 m2) | F26: Cantidad (ha) | G26: Dias | H26: Costo Unitario (soles) | I26: Costo Unitario (Dolares) | J26: Costo Total (Dólares) | K26: Costo Total (Dólares) * Ha
A27: 3 | B27: Maquinaria - Serivicio | C27: Mochila manual | D27: Hora | E27: 0.5 | F27: 3 | G27: 1 | H27: 10 | I27: =H27/$M$11 -> 2.9585799 | J27: =I27*E27*G27 -> 1.4792899 | K27: =F27*G27*I27 -> 8.8757396
A28: 4 | B28: Maquinaria - Serivicio | C28: Mochila manual | D28: Hora | E28: 0.5 | F28: 3 | G28: 1 | H28: 10 | I28: =H28/$M$11 -> 2.9585799 | J28: =I28*E28*G28 -> 1.4792899 | K28: =F28*G28*I28 -> 8.8757396
A29: 5 | B29: Maquinaria - Serivicio | C29: Palanas | D29: Unidad | E29: 1 | F29: 2 | G29: 1 | H29: 4 | I29: 1.18 | J29: =I29*E29*G29 -> 1.18 | K29: =F29*G29*I29 -> 2.36
B30: Maquinaria - Serivicio | C30: Sierra | D30: Unidad | E30: 1 | F30: 1 | G30: 1 | H30: 4 | I30: 1.18 | J30: =I30*E30*G30 -> 1.18 | K30: =F30*G30*I30 -> 1.18
B31: Maquinaria - Serivicio | C31: Picotas | D31: Unidad | E31: 2 | F31: 4 | G31: 1 | H31: 4 | I31: 1.18 | J31: =I31*E31*G31 -> 2.36 | K31: =F31*G31*I31 -> 4.72
A32: TOTAL | B32: - | C32: - | D32: - | E32: - | G32: - | H32: =SUM(H27:H31) -> 32 | I32: =SUM(I27:I31) -> 9.4571598 | J32: =SUM(J27:J31) -> 7.6785799 | K32: =SUM(K27:K31) -> 26.011479
C36: TOTAL MAQUINARIA - INSUMOS - HA | D36: =K13+K21+K32 -> 76.312308
C40: TOTAL MAQUINARIA - INSUMOS - 88M2 | D40: =J13+J21+J32 -> 31.34574

Sheet Proyeccion
B4: Mes - Diciembre
B5: Semana (Lunes- Viernes) | C5: Rubro | D5: Actividad | E5: Unidad | F5: Cantidad | G5: Cantidad en Ha | H5: Dias | I5: Costo Unitario (soles) | J5: Costo Unitario (Dolares) | K5: Costo Total (Dólares) | L5: Costo Total (Dólares) * Ha
B6: 1 | C6: Mano de obra | D6: Pasajes(Ida y Vuelta) | E6: Por personal | F6: 2 | G6: 4 | H6: 6 | I6: 3 | J6: =I6/$N$9 -> 0.88757396 | K6: =J6*F6*H6 -> 10.650888 | L6: =G6*J6*H6 -> 21.301775
D7: Riego diario| | E7: Horas | F7: 2 | G7: 4 | H7: 6 | I7: =12.68 -> 12.68 | J7: =I7/$N$9 -> 3.7514793 | K7: =J7*F7*H7 -> 45.017751 | L7: =G7*J7*H7 -> 90.035503
B8: 2 | C8: Mano de obra | D8: Pasajes(Ida y Vuelta) | E8: Por personal | F8: 2 | G8: 4 | H8: 6 | I8: 3 | J8: =I8/$N$9 -> 0.88757396 | K8: =J8*F8*H8 -> 10.650888 | L8: =G8*J8*H8 -> 21.301775
D9: Riego diario| | E9: Horas | F9: 1 | G9: 4 | H9: 6 | I9: =I7 -> 12.68 | J9: =I9/$N$9 -> 3.7514793 | K9: =J9*F9*H9 -> 22.508876 | L9: =G9*J9*H9 -> 90.035503 | N9: 3.38
B10: 3 | C10: Mano de obra | D10: Pasajes(Ida y Vuelta) | E10: Por personal | F10: 2 | G10: 4 | H10: 6 | I10: 3 | J10: =I10/$N$9 -> 0.88757396 | K10: =J10*F10*H10 -> 10.650888 | L10: =G10*J10*H10 -> 21.301775
C11: Mano de obra | D11: Riego diario| | E11: Horas | F11: 3 | G11: 4 | H11: 6 | I11: =I7 -> 12.68 | J11: =I11/$N$9 -> 3.7514793 | K11: =J11*F11*H11 -> 67.526627 | L11: =G11*J11*H11 -> 90.035503
C12: Maquinaria - servicios | D12: Mochila manual | E12: Unidad | F12: 0.5 | G12: 3 | H12: 1 | I12: 10 | J12: =I12/$N$9 -> 2.9585799 | K12: =J12*F12*H12 -> 1.4792899 | L12: =G12*J12*H12 -> 8.8757396
B13: 4 | C13: Mano de obra | D13: Pasajes(Ida y Vuelta) | E13: Por personal | F13: 2 | G13: 4 | H13: 6 | I13: 3 | J13: =I13/$N$9 -> 0.88757396 | K13: 10.650888 | L13: =G13*J13*H13 -> 21.301775
C14: Mano de obra | D14: Riego diario| | E14: Horas | F14: 3 | G14: 4 | H14: 6 | I14: 12.68 | J14: =I14/$N$9 -> 3.7514793 | K14: 135 | L14: =G14*H14*J14 -> 90.035503
C15: Maquinaria - servicios | D15: Mochila manual | E15: Unidad | F15: 0.5 | G15: 3 | H15: 1 | I15: 10 | J15: =I15/$N$9 -> 2.9585799 | K15: 1.4792899 | L15: =G15*H15*J15 -> 8.8757396
B16: 5 | C16: Mano de obra | D16: Pasajes(Ida y Vuelta) | E16: Por personal | F16: 2 | G16: 4 | H16: 3 | I16: 3 | J16: =I16/$N$9 -> 0.88757396 | K16: 10.650888 | L16: =G16*J16*H16 -> 10.650888
C17: Mano de obra | D17: Riego diario| | E17: Horas | F17: 3 | G17: 4 | H17: 3 | I17: 12.68 | J17: =I17/$N$9 -> 3.7514793 | K17: 135 | L17: =G17*H17*J17 -> 45.017751
C18: Maquinaria - servicios | D18: Mochila manual | E18: Unidad | F18: 0.5 | G18: 3 | H18: 1 | I18: 10 | J18: =I18/$N$9 -> 2.9585799 | K18: 1.4792899 | L18: =G18*H18*J18 -> 8.8757396
B19: TOTAL | L19: =SUM(L6:L18) -> 527.64497
B20: Otros | C20: Agua | I20: 400 | J20: =SUM(J9:J19) -> 26.544379 | L20: =J20 -> 26.544379
C21: Alquiler de terreno | I21: 5000 | J21: =SUM(J10:J20) -> 49.337278 | L21: =J21 -> 49.337278
B22: TOTAL | C22: TOTAL | L22: =SUM(L19:L21) -> 603.52663
B26: Mes - Enero
B27: Semana (Lunes- Viernes) | C27: Rubro | D27: Actividad | E27: Unidad | F27: Cantidad | G27: Cantidad en Ha | H27: Dias | I27: Costo Unitario (soles) | J27: Costo Unitario (Dolares) | K27: Costo Total (Dólares) | L27: Costo Total (Dólares) * Ha
B28: 1 | C28: Mano de obra | D28: Pasajes(Ida y Vuelta) | E28: Por personal | F28: 2 | G28: 4 | H28: 3 | I28: 3 | J28: =I28/$N$32 -> 0.88757396 | K28: =J28*F28*H28 -> 5.3254438 | L28: =G28*J28*H28 -> 10.650888
D29: Riego diario| | E29: Horas | F29: 2 | G29: 4 | H29: 3 | I29: =12.68 -> 12.68 | J29: =I29/$N$32 -> 3.7514793 | K29: =J29*F29*H29 -> 22.508876 | L29: =G29*J29*H29 -> 45.017751
B30: 2 | C30: Mano de obra | D30: Pasajes(Ida y Vuelta) | E30: Por personal | F30: 2 | G30: 4 | H30: 6 | I30: 3 | J30: =I30/$N$32 -> 0.88757396 | K30: =J30*F30*H30 -> 10.650888 | L30: =G30*J30*H30 -> 21.301775
D31: Riego diario| | E31: Horas | F31: 1 | G31: 4 | H31: 6 | I31: =I29 -> 12.68 | J31: =I31/$N$32 -> 3.7514793 | K31: =J31*F31*H31 -> 22.508876 | L31: =G31*J31*H31 -> 90.035503
B32: 3 | C32: Mano de obra | D32: Pasajes(Ida y Vuelta) | E32: Por personal | F32: 2 | G32: 4 | H32: 6 | I32: 3 | J32: =I32/$N$32 -> 0.88757396 | K32: =J32*F32*H32 -> 10.650888 | L32: =G32*J32*H32 -> 21.301775 | N32: 3.38
C33: Mano de obra | D33: Riego diario| | E33: Horas | F33: 3 | G33: 4 | H33: 6 | I33: =I29 -> 12.68 | J33: =I33/$N$32 -> 3.7514793 | K33: =J33*F33*H33 -> 67.526627 | L33: =G33*J33*H33 -> 90.035503
C34: Maquinaria - servicios | D34: Mochila manual | E34: Unidad | F34: 0.5 | G34: 3 | H34: 1 | I34: 10 | J34: =I34/$N$32 -> 2.9585799 | K34: =J34*F34*H34 -> 1.4792899 | L34: =G34*J34*H34 -> 8.8757396
B35: 4 | C35: Mano de obra | D35: Pasajes(Ida y Vuelta) | E35: Por personal | F35: 2 | G35: 4 | H35: 6 | I35: 3 | J35: =I35/$N$32 -> 0.88757396 | K35: 10.650888 | L35: =G35*J35*H35 -> 21.301775
C36: Mano de obra | D36: Riego diario| | E36: Horas | F36: 3 | G36: 4 | H36: 6 | I36: 12.68 | J36: =I36/$N$32 -> 3.7514793 | K36: 135 | L36: =G36*H36*J36 -> 90.035503
C37: Maquinaria - servicios | D37: Mochila manual | E37: Unidad | F37: 0.5 | G37: 3 | H37: 1 | I37: 10 | J37: =I37/$N$32 -> 2.9585799 | K37: 1.4792899 | L37: =G37*H37*J37 -> 8.8757396
B38: 5 | C38: Mano de obra | D38: Pasajes(Ida y Vuelta) | E38: Por personal | F38: 2 | G38: 4 | H38: 6 | I38: 3 | J38: =I38/$N$32 -> 0.88757396 | K38: 10.650888 | L38: =G38*J38*H38 -> 21.301775
C39: Mano de obra | D39: Riego diario| | E39: Horas | F39: 3 | G39: 4 | H39: 6 | I39: 12.68 | J39: =I39/$N$32 -> 3.7514793 | K39: 135 | L39: =G39*H39*J39 -> 90.035503
C40: Maquinaria - servicios | D40: Mochila manual | E40: Unidad | F40: 0.5 | G40: 3 | H40: 1 | I40: 10 | J40: =I40/$N$32 -> 2.9585799 | K40: 1.4792899 | L40: =G40*H40*J40 -> 8.8757396
B41: Total | K41: =SUM(K28:K40) -> 434.91124 | L41: =SUM(L28:L40) -> 527.64497
B46: Mes - Febrero
B47: Semana (Lunes- Viernes) | C47: Rubro | D47: Actividad | E47: Unidad | F47: Cantidad | G47: Cantidad en Ha | H47: Dias | I47: Costo Unitario (soles) | J47: Costo Unitario (Dolares) | K47: Costo Total (Dólares) | L47: Costo Total (Dólares) * Ha
B48: 1 | C48: Mano de obra | D48: Pasajes(Ida y Vuelta) | E48: Por personal | F48: 2 | G48: 4 | H48: 1 | I48: 3 | J48: =I48/$N$52 -> 0.88757396 | K48: =J48*F48*H48 -> 1.7751479 | L48: =G48*J48*H48 -> 3.5502959
D49: Riego diario| | E49: Horas | F49: 2 | G49: 4 | H49: 1 | I49: =12.68 -> 12.68 | J49: =I49/$N$52 -> 3.7514793 | K49: =J49*F49*H49 -> 7.5029586 | L49: =G49*J49*H49 -> 15.005917
B50: 2 | C50: Mano de obra | D50: Pasajes(Ida y Vuelta) | E50: Por personal | F50: 2 | G50: 4 | H50: 6 | I50: 3 | J50: =I50/$N$52 -> 0.88757396 | K50: =J50*F50*H50 -> 10.650888 | L50: =G50*J50*H50 -> 21.301775
...

Sheet Indicador economico
B3: INDICADORES ECONÓMICOS
B6: MES | C6: Flujo de Egresos | D6: Flujo de Ingresos | E6: Flujo - Efectivo Neto | F6: Flujo - Efec. Acumulado | H6: Tasa anual de descuento anual | I6: 0.1
B7: 0 | C7: ='Costeo General'!K23 -> 465.5503 | D7: 0 | E7: =D7-C7 -> -465.5503 | H7: Tasa anual de descuento mensual | I7: =I6/12 -> 0.0083333333 | L7: 3.38
B8: 1 | C8: ='Costeo General'!K50 -> 718.67669 | D8: 0 | E8: =D8-C8 -> -718.67669 | F8: =E8 -> -718.67669
B9: 2 | C9: ='Costeo General'!K78 -> 3266.7811 | D9: 0 | E9: =D9-C9 -> -3266.7811 | F9: =SUM(E8:E9) -> -3985.4578
B10: 3 | C10: =Proyeccion!L22 -> 603.52663 | D10: 0 | E10: =D10-C10 -> -603.52663 | F10: =SUM(E8:E10) -> -4588.9844 | K10: 30 | L10: =J14/L7 -> 2.6259585
B11: 4 | C11: =Proyeccion!L41 -> 527.64497 | D11: 0 | E11: =D11-C11 -> -527.64497 | F11: =SUM(E8:E11) -> -5116.6293
B12: 6 | C12: =Proyeccion!L58 -> 370.31953 | D12: =G22*I22 -> 9200 | E12: =D12-C12 -> 8829.6805 | F12: =SUM(E8:E12) -> 3713.0511
B13: Σ | C13: =SUM(C7:C12) -> 5952.4992 | D13: =SUM(D7:D12) -> 9200
I14: 1kilo | J14: =K10/L7 -> 8.8757396
I15: ='HOJA BASICA'!C8 -> 15000 | J15: x
I17: =(I15*J14) -> 133136.09
B18: =IRR(E7:E12) -> 0.1611458 | C18: TIR
B20: {=NPV(I7,E8:E12)+E7} -> 2980.3998 | C20: VAN
I21: 1 | J21: 3.38
B22: {=((NPV(I7,E8:E12))/-E7)} -> 7.4018857 | C22: B/C | G22: 10000 | I22: 0.92 | J22: 3.5

Sheet x
E2: GRUPO | F2: FERTILIZANTE | H2: mg / L | I2: gr / L | J2: gr / L / dias | K2: gr / dias / volumen total
E3: 1 | F3: UREA | H3: 36.259 | I3: 0.036259 | J3: 0.254 | K3: 12.691 | M3: Sumatoria G1 | O3: N° Usos en Kilo
F4: FOSFATO MONOAMONICO | H4: 4.918 | I4: 0.004918 | J4: 0.034 | K4: 1.721 | M4: =SUM(K3:K5) -> 31.239 | O4: =1000/M4 -> 32.011268
F5: SULFATO DE POTASIO | H5: 48.077 | I5: 0.048077 | J5: 0.337 | K5: 16.827
E6: 2 | F6: SULFATO DE MAGNESIO | H6: 37.5 | I6: 0.0375 | J6: 0.263 | K6: 13.125 | M6: Concentracion en Gr/Ha | N6: =((10000*M4)/88)/1000 -> 3.5498864
F7: SULFATO DE COBRE | H7: 0.4 | I7: 0.0004 | J7: 0.003 | K7: 0.14
F8: SULFATO DE MANGANESO | H8: 2.581 | I8: 0.002581 | J8: 0.018 | K8: 0.903 | M8: Sumatoria G2 | O8: N° Usos de Kilo
F9: SULFATO DE ZINC | H9: 0.698 | I9: 0.000698 | J9: 0.005 | K9: 0.244 | M9: =SUM(K6:K9) -> 14.412 | O9: =1000/M9 -> 69.386622
E10: 3 | F10: BORO | H10: 4.571 | I10: 0.004571 | J10: 0.032 | K10: 1.6
E11: 4 | F11: NITRATO DE CALCIO | H11: 75.472 | I11: 0.075472 | J11: 0.528 | K11: 26.415 | M11: Concentracion en Gr/Ha | N11: =((10000*M9)/88)/1000 -> 1.6377273
M14: Sumatoria G3 | O14: N° Usos de Kilo
M15: =SUM(K10:K11) -> 28.015 | O15: =1000/M15 -> 35.695163
M17: Concentracion en Gr/Ha | N17: =((10000*M15)/88)/1000 -> 3.1835227
